package java15_0315;

public class ExceptionTest {
    //try catch
    //try{
    //  要被执行的正常逻辑
    //}
    //catch{
    //  出现异常之后的错误处理逻辑
    //}
    //finally{
    //异常的出口
    //}
    public static void main(String[] args) {
        // System.out.println(10/0);
//        int[] arr={1,2,3,4,5};
//        System.out.println(arr[100]);
//        try {
//            String str = null;
//            System.out.println(str.length());
//        }catch (NullPointerException e){
//           e.printStackTrace();
//        }
//        System.out.println("我是一行日志");

//        try {
//            func1();
//        } catch (NullPointerException e) {
//            e.printStackTrace();
//        }
    }

//    public static void func1(){
//        func2();
//    }
//    public static void func2(){
//        String str=null;
//        System.out.println(str.length());
//    }
}
